Workbook

Sheet How to use
B1: Yuvoy supply tracker
B2: One row per business. Start with Andaman; add any destination in India the same way.
B4: Filling it in
B5: • Add operators on the Operators tab, one per row. Each row already has a fixed ID (Y0001, Y0002…) that stays with it when you sort or delete rows.
B6: • Destination, Category, Source, Status and Audit result are dropdowns. Pick from the list so the Summary can count them.
B7: • Row 2 is an EXAMPLE showing the expected format. Delete it once you've seen it; it is never counted.
B8: • Rows 3–8 are Havelock dive operators found in web research. Only frogman.in is confirmed; verify the others before contacting.
B9: • Phone numbers: write them with +91 (e.g. +91 94340 00000). Dates: any date format; they display as dd-mmm-yyyy.
B10: • Red licence expiry = expires within 30 days (or already expired). Orange next-action date = overdue.
B12: Status: move each operator left to right
B13: Lead → Contacted → Met → Audited → Signed → Filmed → Live. Rejected and Dormant are off-ramps. Meanings are on the Lists tab.
B15: Where to find operators
... B29: Legend: on the Operators tab, white cells are for you to fill in; grey ID cells fill themselves; row 2 (grey italic) is the example.

Sheet Operators
A1: ID | B1: Business name | C1: Destination | D1: State | E1: Category 1 | F1: Category 2 | G1: Phone / WhatsApp | H1: Email | I1: Website | J1: Instagram | K1: Address / area | L1: Google Maps link | M1: Source | N1: Source link | O1: Status | P1: Owner | Q1: Last contact | R1: Next action | S1: Next action date | T1: Price from (₹) | U1: Licence / permit no. | V1: Licence expiry | W1: PADI / SSI no. | X1: Audit result | Y1: Notes
A2: EX | B2: EXAMPLE – Coral Reef Divers (delete this row) | C2: Havelock (Swaraj Dweep) | D2: IN-AN | E2: Scuba diving | F2: Snorkelling | G2: +91 94340 00000 | H2: hello@example.com | I2: example.com | J2: @coralreefdivers | K2: Beach No. 3 | M2: Field team | O2: Met | P2: Rahul | Q2: 46296 | R2: Send audit checklist | S2: 46303 | T2: 4500 | U2: AN/WS/123 | V2: 46477 | W2: S-12345 | X2: Not started | Y2: Shows the expected format for each column.
A3: Y0001 | B3: Frogman (frogman.in) | C3: Havelock (Swaraj Dweep) | D3: IN-AN | E3: Scuba diving | I3: frogman.in | M3: Field team | O3: Signed | P3: Rahul | X3: Not started | Y3: Anchor operator (co-founder owned). Keep its bookings separate when tracking the non-anchor share.
A4: Y0002 | B4: Havelock Divers | C4: Havelock (Swaraj Dweep) | D4: IN-AN | E4: Scuba diving | M4: Marketplace | N4: https://www.tripadvisor.in/Attraction_Review-g503691-d12921588-Reviews-Havelock_Divers-Havelock_Island_Andaman_and_Nicobar_Islands.html | O4: Lead | Y4: Found in web research; verify contact details.
A5: Y0003 | B5: Barefoot Scuba | C5: Havelock (Swaraj Dweep) | D5: IN-AN | E5: Scuba diving | M5: Web search | O5: Lead | Y5: Named in research as offering discovery dives from ₹4,500; verify.
A6: Y0004 | B6: Dive India | C6: Havelock (Swaraj Dweep) | D6: IN-AN | E6: Scuba diving | M6: Web search | O6: Lead | Y6: Named in research as offering discovery dives from ₹4,500; verify.
A7: Y0005 | B7: Waterwoods | C7: Havelock (Swaraj Dweep) | D7: IN-AN | E7: Scuba diving | I7: waterwoods.in | M7: Web search | N7: https://www.waterwoods.in/havelock/activities/scuba-diving/ | O7: Lead | Y7: Found in web research; verify.
A8: Y0006 | B8: Dive Andaman | C8: Havelock (Swaraj Dweep) | D8: IN-AN | E8: Scuba diving | I8: diveandaman.com | M8: Web search | N8: https://www.diveandaman.com/diving-packages-in-havelock-island | O8: Lead | Y8: Found in web research; verify.
A9: Y0007
A10: Y0008
A11: Y0009
A12: Y0010
A13: Y0011
A14: Y0012
A15: Y0013
A16: Y0014
A17: Y0015
A18: Y0016
A19: Y0017
A20: Y0018
... A1001: Y0999

Sheet Summary
A1: Yuvoy supply: summary
A2: Updates automatically from the Operators tab. Rows whose name starts with "EXAMPLE" are not counted.
A4: Headline
A5: Operators in tracker | B5: =COUNTIFS(Operators!$B$2:$B$1001,"<>",Operators!$B$2:$B$1001,"<>EXAMPLE*") -> 6
A6: Contacted or further | B6: =B5-COUNTIFS(Operators!$O$2:$O$1001,"Lead",Operators!$B$2:$B$1001,"<>EXAMPLE*")-COUNTIFS(Operators!$O$2:$O$1001,"",Operators!$B$2:$B$1001,"<>",Operators!$B$2:$B$1001,"<>EXAMPLE*")-COUNTIFS(Operators!$O$2:$O$1001,"Rejected",Operators!$B$2:$B$1001,"<>EXAMPLE*")-COUNTIFS(Operators!$O$2:$O$1001,"Dormant",Operators!$B$2:$B$1001,"<>EXAMPLE*") -> 1
A7: Live on Yuvoy | B7: =COUNTIFS(Operators!$O$2:$O$1001,"Live",Operators!$B$2:$B$1001,"<>EXAMPLE*") -> 0
A8: With phone / WhatsApp | B8: =COUNTIFS(Operators!$G$2:$G$1001,"<>",Operators!$B$2:$B$1001,"<>EXAMPLE*") -> 0
A9: % with phone / WhatsApp | B9: =IF(B5=0,0,B8/B5) -> 0
A10: Licences expiring ≤30 days | B10: =COUNTIFS(Operators!$V$2:$V$1001,"<="&(TODAY()+30),Operators!$B$2:$B$1001,"<>EXAMPLE*") -> 0
A12: Pipeline
A13: Status | B13: Operators | C13: Meaning
A14: Lead | B14: =COUNTIFS(Operators!$O$2:$O$1001,A14,Operators!$B$2:$B$1001,"<>EXAMPLE*") -> 5 | C14: Found, not contacted yet
A15: Contacted | B15: =COUNTIFS(Operators!$O$2:$O$1001,A15,Operators!$B$2:$B$1001,"<>EXAMPLE*") -> 0 | C15: First message or call sent
A16: Met | B16: =COUNTIFS(Operators!$O$2:$O$1001,A16,Operators!$B$2:$B$1001,"<>EXAMPLE*") -> 0 | C16: Met in person or on a call
A17: Audited | B17: =COUNTIFS(Operators!$O$2:$O$1001,A17,Operators!$B$2:$B$1001,"<>EXAMPLE*") -> 0 | C17: Passed the pre-signing audit (licences, safety, quality)
A18: Signed | B18: =COUNTIFS(Operators!$O$2:$O$1001,A18,Operators!$B$2:$B$1001,"<>EXAMPLE*") -> 1 | C18: Agreed terms (15% commission, cancellation, content rights)
A19: Filmed | B19: =COUNTIFS(Operators!$O$2:$O$1001,A19,Operators!$B$2:$B$1001,"<>EXAMPLE*") -> 0 | C19: Video shot and approved
A20: Live | B20: =COUNTIFS(Operators!$O$2:$O$1001,A20,Operators!$B$2:$B$1001,"<>EXAMPLE*") -> 0 | C20: Listed and bookable on Yuvoy
A21: Rejected | B21: =COUNTIFS(Operators!$O$2:$O$1001,A21,Operators!$B$2:$B$1001,"<>EXAMPLE*") -> 0 | C21: Failed audit or not a fit
A22: Dormant | B22: =COUNTIFS(Operators!$O$2:$O$1001,A22,Operators!$B$2:$B$1001,"<>EXAMPLE*") -> 0 | C22: Not now; revisit later
A25: By destination
A26: Destination | B26: Operators | C26: Contacted+ | D26: Signed / filmed / live | E26: Mode
A27: Andaman Islands | B27: =COUNTIFS(Operators!$C$2:$C$1001,A27,Operators!$B$2:$B$1001,"<>EXAMPLE*") -> 0 | C27: =B27-COUNTIFS(Operators!$C$2:$C$1001,A27,Operators!$O$2:$O$1001,"Lead",Operators!$B$2:$B$1001,"<>EXAMPLE*")-COUNTIFS(Operators!$C$2:$C$1001,A27,Operators!$O$2:$O$1001,"",Operators!$B$2:$B$1001,"<>EXAMPLE*")-COUNTIFS(Operators!$C$2:$C$1001,A27,Operators!$O$2:$O$1001,"Rejected",Operators!$B$2:$B$1001,"<>EXAMPLE*")-COUNTIFS(Operators!$C$2:$C$1001,A27,Operators!$O$2:$O$1001,"Dormant",Operators!$B$2:$B$1001,"<>EXAMPLE*") -> 0 | D27: =COUNTIFS(Operators!$C$2:$C$1001,A27,Operators!$O$2:$O$1001,"Signed",Operators!$B$2:$B$1001,"<>EXAMPLE*")+COUNTIFS(Operators!$C$2:$C$1001,A27,Operators!$O$2:$O$1001,"Filmed",Operators!$B$2:$B$1001,"<>EXAMPLE*")+COUNTIFS(Operators!$C$2:$C$1001,A27,Operators!$O$2:$O$1001,"Live",Operators!$B$2:$B$1001,"<>EXAMPLE*") -> 0 | E27: Travel
A28: Havelock (Swaraj Dweep) | B28: =COUNTIFS(Operators!$C$2:$C$1001,A28,Operators!$B$2:$B$1001,"<>EXAMPLE*") -> 6 | C28: =B28-COUNTIFS(Operators!$C$2:$C$1001,A28,Operators!$O$2:$O$1001,"Lead",Operators!$B$2:$B$1001,"<>EXAMPLE*")-COUNTIFS(Operators!$C$2:$C$1001,A28,Operators!$O$2:$O$1001,"",Operators!$B$2:$B$1001,"<>EXAMPLE*")-COUNTIFS(Operators!$C$2:$C$1001,A28,Operators!$O$2:$O$1001,"Rejected",Operators!$B$2:$B$1001,"<>EXAMPLE*")-COUNTIFS(Operators!$C$2:$C$1001,A28,Operators!$O$2:$O$1001,"Dormant",Operators!$B$2:$B$1001,"<>EXAMPLE*") -> 1 | D28: =COUNTIFS(Operators!$C$2:$C$1001,A28,Operators!$O$2:$O$1001,"Signed",Operators!$B$2:$B$1001,"<>EXAMPLE*")+COUNTIFS(Operators!$C$2:$C$1001,A28,Operators!$O$2:$O$1001,"Filmed",Operators!$B$2:$B$1001,"<>EXAMPLE*")+COUNTIFS(Operators!$C$2:$C$1001,A28,Operators!$O$2:$O$1001,"Live",Operators!$B$2:$B$1001,"<>EXAMPLE*") -> 1 | E28: Travel
A29: Neil (Shaheed Dweep) | B29: =COUNTIFS(Operators!$C$2:$C$1001,A29,Operators!$B$2:$B$1001,"<>EXAMPLE*") -> 0 | C29: =B29-COUNTIFS(Operators!$C$2:$C$1001,A29,Operators!$O$2:$O$1001,"Lead",Operators!$B$2:$B$1001,"<>EXAMPLE*")-COUNTIFS(Operators!$C$2:$C$1001,A29,Operators!$O$2:$O$1001,"",Operators!$B$2:$B$1001,"<>EXAMPLE*")-COUNTIFS(Operators!$C$2:$C$1001,A29,Operators!$O$2:$O$1001,"Rejected",Operators!$B$2:$B$1001,"<>EXAMPLE*")-COUNTIFS(Operators!$C$2:$C$1001,A29,Operators!$O$2:$O$1001,"Dormant",Operators!$B$2:$B$1001,"<>EXAMPLE*") -> 0 | D29: =COUNTIFS(Operators!$C$2:$C$1001,A29,Operators!$O$2:$O$1001,"Signed",Operators!$B$2:$B$1001,"<>EXAMPLE*")+COUNTIFS(Operators!$C$2:$C$1001,A29,Operators!$O$2:$O$1001,"Filmed",Operators!$B$2:$B$1001,"<>EXAMPLE*")+COUNTIFS(Operators!$C$2:$C$1001,A29,Operators!$O$2:$O$1001,"Live",Operators!$B$2:$B$1001,"<>EXAMPLE*") -> 0 | E29: Travel
A30: Port Blair (Sri Vijaya Puram) | B30: =COUNTIFS(Operators!$C$2:$C$1001,A30,Operators!$B$2:$B$1001,"<>EXAMPLE*") -> 0 | C30: =B30-COUNTIFS(Operators!$C$2:$C$1001,A30,Operators!$O$2:$O$1001,"Lead",Operators!$B$2:$B$1001,"<>EXAMPLE*")-COUNTIFS(Operators!$C$2:$C$1001,A30,Operators!$O$2:$O$1001,"",Operators!$B$2:$B$1001,"<>EXAMPLE*")-COUNTIFS(Operators!$C$2:$C$1001,A30,Operators!$O$2:$O$1001,"Rejected",Operators!$B$2:$B$1001,"<>EXAMPLE*")-COUNTIFS(Operators!$C$2:$C$1001,A30,Operators!$O$2:$O$1001,"Dormant",Operators!$B$2:$B$1001,"<>EXAMPLE*") -> 0 | D30: =COUNTIFS(Operators!$C$2:$C$1001,A30,Operators!$O$2:$O$1001,"Signed",Operators!$B$2:$B$1001,"<>EXAMPLE*")+COUNTIFS(Operators!$C$2:$C$1001,A30,Operators!$O$2:$O$1001,"Filmed",Operators!$B$2:$B$1001,"<>EXAMPLE*")+COUNTIFS(Operators!$C$2:$C$1001,A30,Operators!$O$2:$O$1001,"Live",Operators!$B$2:$B$1001,"<>EXAMPLE*") -> 0 | E30: Travel
A31: Leh | B31: =COUNTIFS(Operators!$C$2:$C$1001,A31,Operators!$B$2:$B$1001,"<>EXAMPLE*") -> 0 | C31: =B31-COUNTIFS(Operators!$C$2:$C$1001,A31,Operators!$O$2:$O$1001,"Lead",Operators!$B$2:$B$1001,"<>EXAMPLE*")-COUNTIFS(Operators!$C$2:$C$1001,A31,Operators!$O$2:$O$1001,"",Operators!$B$2:$B$1001,"<>EXAMPLE*")-COUNTIFS(Operators!$C$2:$C$1001,A31,Operators!$O$2:$O$1001,"Rejected",Operators!$B$2:$B$1001,"<>EXAMPLE*")-COUNTIFS(Operators!$C$2:$C$1001,A31,Operators!$O$2:$O$1001,"Dormant",Operators!$B$2:$B$1001,"<>EXAMPLE*") -> 0 | D31: =COUNTIFS(Operators!$C$2:$C$1001,A31,Operators!$O$2:$O$1001,"Signed",Operators!$B$2:$B$1001,"<>EXAMPLE*")+COUNTIFS(Operators!$C$2:$C$1001,A31,Operators!$O$2:$O$1001,"Filmed",Operators!$B$2:$B$1001,"<>EXAMPLE*")+COUNTIFS(Operators!$C$2:$C$1001,A31,Operators!$O$2:$O$1001,"Live",Operators!$B$2:$B$1001,"<>EXAMPLE*") -> 0 | E31: Travel
A32: Ladakh | B32: =COUNTIFS(Operators!$C$2:$C$1001,A32,Operators!$B$2:$B$1001,"<>EXAMPLE*") -> 0 | C32: =B32-COUNTIFS(Operators!$C$2:$C$1001,A32,Operators!$O$2:$O$1001,"Lead",Operators!$B$2:$B$1001,"<>EXAMPLE*")-COUNTIFS(Operators!$C$2:$C$1001,A32,Operators!$O$2:$O$1001,"",Operators!$B$2:$B$1001,"<>EXAMPLE*")-COUNTIFS(Operators!$C$2:$C$1001,A32,Operators!$O$2:$O$1001,"Rejected",Operators!$B$2:$B$1001,"<>EXAMPLE*")-COUNTIFS(Operators!$C$2:$C$1001,A32,Operators!$O$2:$O$1001,"Dormant",Operators!$B$2:$B$1001,"<>EXAMPLE*") -> 0 | D32: =COUNTIFS(Operators!$C$2:$C$1001,A32,Operators!$O$2:$O$1001,"Signed",Operators!$B$2:$B$1001,"<>EXAMPLE*")+COUNTIFS(Operators!$C$2:$C$1001,A32,Operators!$O$2:$O$1001,"Filmed",Operators!$B$2:$B$1001,"<>EXAMPLE*")+COUNTIFS(Operators!$C$2:$C$1001,A32,Operators!$O$2:$O$1001,"Live",Operators!$B$2:$B$1001,"<>EXAMPLE*") -> 0 | E32: Travel
A33: Spiti (Kaza) | B33: =COUNTIFS(Operators!$C$2:$C$1001,A33,Operators!$B$2:$B$1001,"<>EXAMPLE*") -> 0 | C33: =B33-COUNTIFS(Operators!$C$2:$C$1001,A33,Operators!$O$2:$O$1001,"Lead",Operators!$B$2:$B$1001,"<>EXAMPLE*")-COUNTIFS(Operators!$C$2:$C$1001,A33,Operators!$O$2:$O$1001,"",Operators!$B$2:$B$1001,"<>EXAMPLE*")-COUNTIFS(Operators!$C$2:$C$1001,A33,Operators!$O$2:$O$1001,"Rejected",Operators!$B$2:$B$1001,"<>EXAMPLE*")-COUNTIFS(Operators!$C$2:$C$1001,A33,Operators!$O$2:$O$1001,"Dormant",Operators!$B$2:$B$1001,"<>EXAMPLE*") -> 0 | D33: =COUNTIFS(Operators!$C$2:$C$1001,A33,Operators!$O$2:$O$1001,"Signed",Operators!$B$2:$B$1001,"<>EXAMPLE*")+COUNTIFS(Operators!$C$2:$C$1001,A33,Operators!$O$2:$O$1001,"Filmed",Operators!$B$2:$B$1001,"<>EXAMPLE*")+COUNTIFS(Operators!$C$2:$C$1001,A33,Operators!$O$2:$O$1001,"Live",Operators!$B$2:$B$1001,"<>EXAMPLE*") -> 0 | E33: Travel
A34: Manali | B34: =COUNTIFS(Operators!$C$2:$C$1001,A34,Operators!$B$2:$B$1001,"<>EXAMPLE*") -> 0 | C34: =B34-COUNTIFS(Operators!$C$2:$C$1001,A34,Operators!$O$2:$O$1001,"Lead",Operators!$B$2:$B$1001,"<>EXAMPLE*")-COUNTIFS(Operators!$C$2:$C$1001,A34,Operators!$O$2:$O$1001,"",Operators!$B$2:$B$1001,"<>EXAMPLE*")-COUNTIFS(Operators!$C$2:$C$1001,A34,Operators!$O$2:$O$1001,"Rejected",Operators!$B$2:$B$1001,"<>EXAMPLE*")-COUNTIFS(Operators!$C$2:$C$1001,A34,Operators!$O$2:$O$1001,"Dormant",Operators!$B$2:$B$1001,"<>EXAMPLE*") -> 0 | D34: =COUNTIFS(Operators!$C$2:$C$1001,A34,Operators!$O$2:$O$1001,"Signed",Operators!$B$2:$B$1001,"<>EXAMPLE*")+COUNTIFS(Operators!$C$2:$C$1001,A34,Operators!$O$2:$O$1001,"Filmed",Operators!$B$2:$B$1001,"<>EXAMPLE*")+COUNTIFS(Operators!$C$2:$C$1001,A34,Operators!$O$2:$O$1001,"Live",Operators!$B$2:$B$1001,"<>EXAMPLE*") -> 0 | E34: Travel
A35: Bir Billing | B35: =COUNTIFS(Operators!$C$2:$C$1001,A35,Operators!$B$2:$B$1001,"<>EXAMPLE*") -> 0 | C35: =B35-COUNTIFS(Operators!$C$2:$C$1001,A35,Operators!$O$2:$O$1001,"Lead",Operators!$B$2:$B$1001,"<>EXAMPLE*")-COUNTIFS(Operators!$C$2:$C$1001,A35,Operators!$O$2:$O$1001,"",Operators!$B$2:$B$1001,"<>EXAMPLE*")-COUNTIFS(Operators!$C$2:$C$1001,A35,Operators!$O$2:$O$1001,"Rejected",Operators!$B$2:$B$1001,"<>EXAMPLE*")-COUNTIFS(Operators!$C$2:$C$1001,A35,Operators!$O$2:$O$1001,"Dormant",Operators!$B$2:$B$1001,"<>EXAMPLE*") -> 0 | D35: =COUNTIFS(Operators!$C$2:$C$1001,A35,Operators!$O$2:$O$1001,"Signed",Operators!$B$2:$B$1001,"<>EXAMPLE*")+COUNTIFS(Operators!$C$2:$C$1001,A35,Operators!$O$2:$O$1001,"Filmed",Operators!$B$2:$B$1001,"<>EXAMPLE*")+COUNTIFS(Operators!$C$2:$C$1001,A35,Operators!$O$2:$O$1001,"Live",Operators!$B$2:$B$1001,"<>EXAMPLE*") -> 0 | E35: Travel
A36: Dharamshala & McLeod Ganj | B36: =COUNTIFS(Operators!$C$2:$C$1001,A36,Operators!$B$2:$B$1001,"<>EXAMPLE*") -> 0 | C36: =B36-COUNTIFS(Operators!$C$2:$C$1001,A36,Operators!$O$2:$O$1001,"Lead",Operators!$B$2:$B$1001,"<>EXAMPLE*")-COUNTIFS(Operators!$C$2:$C$1001,A36,Operators!$O$2:$O$1001,"",Operators!$B$2:$B$1001,"<>EXAMPLE*")-COUNTIFS(Operators!$C$2:$C$1001,A36,Operators!$O$2:$O$1001,"Rejected",Operators!$B$2:$B$1001,"<>EXAMPLE*")-COUNTIFS(Operators!$C$2:$C$1001,A36,Operators!$O$2:$O$1001,"Dormant",Operators!$B$2:$B$1001,"<>EXAMPLE*") -> 0 | D36: =COUNTIFS(Operators!$C$2:$C$1001,A36,Operators!$O$2:$O$1001,"Signed",Operators!$B$2:$B$1001,"<>EXAMPLE*")+COUNTIFS(Operators!$C$2:$C$1001,A36,Operators!$O$2:$O$1001,"Filmed",Operators!$B$2:$B$1001,"<>EXAMPLE*")+COUNTIFS(Operators!$C$2:$C$1001,A36,Operators!$O$2:$O$1001,"Live",Operators!$B$2:$B$1001,"<>EXAMPLE*") -> 0 | E36: Travel
A37: Rishikesh | B37: =COUNTIFS(Operators!$C$2:$C$1001,A37,Operators!$B$2:$B$1001,"<>EXAMPLE*") -> 0 | C37: =B37-COUNTIFS(Operators!$C$2:$C$1001,A37,Operators!$O$2:$O$1001,"Lead",Operators!$B$2:$B$1001,"<>EXAMPLE*")-COUNTIFS(Operators!$C$2:$C$1001,A37,Operators!$O$2:$O$1001,"",Operators!$B$2:$B$1001,"<>EXAMPLE*")-COUNTIFS(Operators!$C$2:$C$1001,A37,Operators!$O$2:$O$1001,"Rejected",Operators!$B$2:$B$1001,"<>EXAMPLE*")-COUNTIFS(Operators!$C$2:$C$1001,A37,Operators!$O$2:$O$1001,"Dormant",Operators!$B$2:$B$1001,"<>EXAMPLE*") -> 0 | D37: =COUNTIFS(Operators!$C$2:$C$1001,A37,Operators!$O$2:$O$1001,"Signed",Operators!$B$2:$B$1001,"<>EXAMPLE*")+COUNTIFS(Operators!$C$2:$C$1001,A37,Operators!$O$2:$O$1001,"Filmed",Operators!$B$2:$B$1001,"<>EXAMPLE*")+COUNTIFS(Operators!$C$2:$C$1001,A37,Operators!$O$2:$O$1001,"Live",Operators!$B$2:$B$1001,"<>EXAMPLE*") -> 0 | E37: Travel
A38: Darjeeling | B38: =COUNTIFS(Operators!$C$2:$C$1001,A38,Operators!$B$2:$B$1001,"<>EXAMPLE*") -> 0 | C38: =B38-COUNTIFS(Operators!$C$2:$C$1001,A38,Operators!$O$2:$O$1001,"Lead",Operators!$B$2:$B$1001,"<>EXAMPLE*")-COUNTIFS(Operators!$C$2:$C$1001,A38,Operators!$O$2:$O$1001,"",Operators!$B$2:$B$1001,"<>EXAMPLE*")-COUNTIFS(Operators!$C$2:$C$1001,A38,Operators!$O$2:$O$1001,"Rejected",Operators!$B$2:$B$1001,"<>EXAMPLE*")-COUNTIFS(Operators!$C$2:$C$1001,A38,Operators!$O$2:$O$1001,"Dormant",Operators!$B$2:$B$1001,"<>EXAMPLE*") -> 0 | D38: =COUNTIFS(Operators!$C$2:$C$1001,A38,Operators!$O$2:$O$1001,"Signed",Operators!$B$2:$B$1001,"<>EXAMPLE*")+COUNTIFS(Operators!$C$2:$C$1001,A38,Operators!$O$2:$O$1001,"Filmed",Operators!$B$2:$B$1001,"<>EXAMPLE*")+COUNTIFS(Operators!$C$2:$C$1001,A38,Operators!$O$2:$O$1001,"Live",Operators!$B$2:$B$1001,"<>EXAMPLE*") -> 0 | E38: Travel
... A64: Ahmedabad | B64: =COUNTIFS(Operators!$C$2:$C$1001,A64,Operators!$B$2:$B$1001,"<>EXAMPLE*") -> 0 | C64: =B64-COUNTIFS(Operators!$C$2:$C$1001,A64,Operators!$O$2:$O$1001,"Lead",Operators!$B$2:$B$1001,"<>EXAMPLE*")-COUNTIFS(Operators!$C$2:$C$1001,A64,Operators!$O$2:$O$1001,"",Operators!$B$2:$B$1001,"<>EXAMPLE*")-COUNTIFS(Operators!$C$2:$C$1001,A64,Operators!$O$2:$O$1001,"Rejected",Operators!$B$2:$B$1001,"<>EXAMPLE*")-COUNTIFS(Operators!$C$2:$C$1001,A64,Operators!$O$2:$O$1001,"Dormant",Operators!$B$2:$B$1001,"<>EXAMPLE*") -> 0 | D64: =COUNTIFS(Operators!$C$2:$C$1001,A64,Operators!$O$2:$O$1001,"Signed",Operators!$B$2:$B$1001,"<>EXAMPLE*")+COUNTIFS(Operators!$C$2:$C$1001,A64,Operators!$O$2:$O$1001,"Filmed",Operators!$B$2:$B$1001,"<>EXAMPLE*")+COUNTIFS(Operators!$C$2:$C$1001,A64,Operators!$O$2:$O$1001,"Live",Operators!$B$2:$B$1001,"<>EXAMPLE*") -> 0 | E64: Local (city)
A66: By category (Category 1 or 2)
A67: Category | B67: Operators | C67: Group
A68: Scuba diving | B68: =COUNTIFS(Operators!$E$2:$E$1001,A68,Operators!$B$2:$B$1001,"<>EXAMPLE*")+COUNTIFS(Operators!$F$2:$F$1001,A68,Operators!$E$2:$E$1001,"<>"&A68,Operators!$B$2:$B$1001,"<>EXAMPLE*") -> 6 | C68: Water
A69: Snorkelling | B69: =COUNTIFS(Operators!$E$2:$E$1001,A69,Operators!$B$2:$B$1001,"<>EXAMPLE*")+COUNTIFS(Operators!$F$2:$F$1001,A69,Operators!$E$2:$E$1001,"<>"&A69,Operators!$B$2:$B$1001,"<>EXAMPLE*") -> 0 | C69: Water
A70: Boat tours & cruises | B70: =COUNTIFS(Operators!$E$2:$E$1001,A70,Operators!$B$2:$B$1001,"<>EXAMPLE*")+COUNTIFS(Operators!$F$2:$F$1001,A70,Operators!$E$2:$E$1001,"<>"&A70,Operators!$B$2:$B$1001,"<>EXAMPLE*") -> 0 | C70: Water
...

Sheet Lists
A1: Destination | B1: State | C1: Type | D1: Mode | F1: Category | G1: Group | H1: Mode | J1: Status | K1: Meaning | M1: Source | N1: What it is | O1: Trust | Q1: Audit result
A2: Andaman Islands | B2: IN-AN | C2: Island | D2: Travel | F2: Scuba diving | G2: Water | H2: Travel | J2: Lead | K2: Found, not contacted yet | M2: Field team | N2: Seen or met on the ground | O2: Highest | Q2: Not started
A3: Havelock (Swaraj Dweep) | B3: IN-AN | C3: Island | D3: Travel | F3: Snorkelling | G3: Water | H3: Travel | J3: Contacted | K3: First message or call sent | M3: Tourism registry | N3: Govt / state tourism lists, water-sports permits | O3: High | Q3: Pass
A4: Neil (Shaheed Dweep) | B4: IN-AN | C4: Island | D4: Travel | F4: Boat tours & cruises | G4: Water | H4: Travel | J4: Met | K4: Met in person or on a call | M4: PADI / SSI | N4: Dive-centre locator | O4: High | Q4: Conditional
A5: Port Blair (Sri Vijaya Puram) | B5: IN-AN | C5: City | D5: Travel | F5: Water sports | G5: Water | H5: Travel | J5: Audited | K5: Passed the pre-signing audit (licences, safety, quality) | M5: ATOAI | N5: Adventure Tour Operators Association of India members | O5: High | Q5: Fail
A6: Leh | B6: IN-LA | C6: Hill | D6: Travel | F6: River rafting | G6: Water | H6: Travel | J6: Signed | K6: Agreed terms (15% commission, cancellation, content rights) | M6: Referral | N6: Recommended by another operator, hotel or guest | O6: Medium
A7: Ladakh | B7: IN-LA | C7: Hill | D7: Travel | F7: Fishing | G7: Water | H7: Travel | J7: Filmed | K7: Video shot and approved | M7: Google Maps | N7: Found on Google Maps | O7: Medium
A8: Spiti (Kaza) | B8: IN-HP | C8: Hill | D8: Travel | F8: Trekking & hiking | G8: Adventure | H8: Travel | J8: Live | K8: Listed and bookable on Yuvoy | M8: Web search | N8: Found online (own website, listings) | O8: Medium
A9: Manali | B9: IN-HP | C9: Hill | D9: Travel | F9: Paragliding & air sports | G9: Adventure | H9: Travel | J9: Rejected | K9: Failed audit or not a fit | M9: Instagram | N9: Found via profile, geotag or hashtag | O9: Low
A10: Bir Billing | B10: IN-HP | C10: Hill | D10: Travel | F10: Climbing & rappelling | G10: Adventure | H10: Weekend | J10: Dormant | K10: Not now; revisit later | M10: Marketplace | N10: Seen on Thrillophilia, Tripadvisor, Klook etc. | O10: Low
A11: Dharamshala & McLeod Ganj | B11: IN-HP | C11: Hill | D11: Travel | F11: Camping & glamping | G11: Adventure | H11: Travel
A12: Rishikesh | B12: IN-UK | C12: Hill | D12: Travel | F12: Wildlife & safari | G12: Adventure | H12: Travel
A13: Darjeeling | B13: IN-WB | C13: Hill | D13: Travel | F13: Snow sports | G13: Adventure | H13: Travel
A14: Gangtok | B14: IN-SK | C14: Hill | D14: Travel | F14: Cycling & motorbike tours | G14: Adventure | H14: Travel
A15: Shillong | B15: IN-ML | C15: Hill | D15: Travel | F15: Ziplines | G15: Adventure | H15: Weekend
A16: North Goa | B16: IN-GA | C16: Beach | D16: Travel | F16: Horse & camel riding | G16: Adventure | H16: Travel
A17: South Goa | B17: IN-GA | C17: Beach | D17: Travel | F17: Guided tours & walks | G17: Culture & heritage | H17: Travel
A18: Gokarna | B18: IN-KA | C18: Beach | D18: Travel | F18: Museums & heritage sites | G18: Culture & heritage | H18: Travel
A19: Varkala | B19: IN-KL | C19: Beach | D19: Travel | F19: Festivals & cultural events | G19: Culture & heritage | H19: Weekend
A20: Alleppey (Alappuzha) | B20: IN-KL | C20: Backwater | D20: Travel | F20: Village & rural experiences | G20: Culture & heritage | H20: Travel
A21: Kochi | B21: IN-KL | C21: City | D21: Travel | F21: Cooking classes | G21: Food & drink | H21: Weekend
A22: Puducherry | B22: IN-PY | C22: Beach | D22: Travel | F22: Food tours | G22: Food & drink | H22: Travel
... A37: Chennai | B37: IN-TN | C37: City | D37: Local (city) | F37: Tour operators & travel agents | G37: Travel agencies & tour operators | H37: Travel
A38: Kolkata | B38: IN-WB | C38: City | D38: Local (city)
A39: Ahmedabad | B39: IN-GJ | C39: City | D39: Local (city)
A40: Other
